Workbook

Sheet Dashboard_Home
A5: BEST TEAM | D5: BEST BATSMAN | G5: BEST BOWLER | J5: BEST CAPTAIN | M5: BEST COACH
A7: =INDEX(Team_Analytics!A:A,MATCH(MAX(Team_Analytics!G:G),Team_Analytics!G:G,0)) -> GT | D7: {=INDEX(Master_Batsman_Analysis!A:A,MATCH(MAX(IF(ISNUMBER(Master_Batsman_Analysis!Q:Q),Master_Batsman_Analysis!Q:Q)),Master_Batsman_Analysis!Q:Q,0))} -> Vaibhav Suryavanshi | G7: =INDEX(Master_Bowler_Analysis!A:A,MATCH(MAX(Master_Bowler_Analysis!Q:Q),Master_Bowler_Analysis!Q:Q,0)) -> Kagiso Rabada | J7: =INDEX(Captain_Clean!A:A,MATCH(MAX(Captain_Clean!G:G),Captain_Clean!G:G,0)) -> Rajat Patidar | M7: =INDEX(Coach_Clean!A:A,MATCH(MAX(Coach_Clean!H:H),Coach_Clean!H:H,0)) -> Mahela Jayawardene
A11: Which teams spent the most? | I11: Which team is strongest overall?
A31: Which team got best output per crore?

Sheet Auction_Intelligence
A6: Which players gave highest performance for lowest price? | J6: Who cost a lot but underperformed?
J8: TOP 5 OVERPRICED PLAYERS
A10: Players | C10: Teams | E10: Price | G10: Value Score | J10: Player | L10: Teams | N10: Price | P10: Overprice Score
A11: 1.Finn Allen | C11: KKR | E11: 2 | G11: 1303.9406 | J11: 1.Akshat Raghuwanshi | L11: LSG | N11: 2.2 | P11: 0.0451023
A12: 2.Pathum Nissanka | C12: DC | E12: 4 | G12: 306.91409 | J12: 2.Kartik Sharma | L12: CSK | N12: 14.2 | P12: 0.010755598
A13: 3.Mukul Choudhary | C13: LSG | E13: 2.6 | G13: 262.40336 | J13: 3.Mukul Choudhary | L13: LSG | N13: 2.6 | P13: 0.0038109269
A14: 4.Kartik Sharma | C14: CSK | E14: 14.2 | G14: 92.974836 | J14: 4.Pathum Nissanka | L14: DC | N14: 4 | P14: 0.0032582408
A15: 5.Akshat Raghuwanshi | C15: LSG | E15: 2.2 | G15: 22.171818 | J15: 5.Finn Allen | L15: KKR | N15: 2 | P15: 0.0007669061
A18: Which role consumed the highest auction budget? | J18: Which low-cost uncapped players can become future stars?
A20: ROLE BUDGET DISTRIBUTION | J20: BEST VALUE UNCAPPPED PLAYERS
J22: Player | L22: Team | M22: Role | O22: Price | Q22: Final Uncapped Score
J23: Emanjot Chahal | L23: RR | M23: All-Rounder | O23: 3 | Q23: 309.61
J26: Prithvi Shaw | L26: DC | M26: Anchor | O26: 0.75 | Q26: 100.02
J29: Brijesh Sharma | L29: RR | M29: Spinner | O29: 0.3 | Q29: 92.97
J32: Gerald Coetzee | L32: SRH | M32: Pacer | O32: 2 | Q32: 72.29
J35: Ruchit Ahir | L35: MI | M35: Anchor | O35: 0.3 | Q35: 66.79
A41: Which teams spent wisely?
A43: TEAM SPENDING EFFICIENCY

Sheet Role_Analytics
A6: BEST ANCHOR | N6: BEST WICKETKEEPER
A9: BASED ON BATTING IMPACT | N9: BASED ON STRIKE RATE
A37: BEST FINISHER | N37: BEST BOWLER
A40: SR v/s B% | N40: BASED ON FINAL BOWLING SCORE

Sheet Leadership_Analytics
A6: COACH ROI | O6: WIN %
A40: Coach Efficiency vs Budget

Sheet Best_XI_2026
I18: VAIBHAV SURYAVANSHI | M18: VIRAT KOHLI
C35: SHUBMAN GILL | K35: HEINRICH KLAASEN | S35: KL RAHUL
K51: HARDIK PANDYA
K68: NITISH KUMAR REDDY
C84: KUNAL PANDYA | K84: HAZELWOOD | T84: RASHID KHAN
K100: KAGISO RABADA

Sheet Master_Player_Analytics
A1: Player | B1: Team | C1: Acquisition | D1: Role | E1: Price | F1: key | G1: Matches | H1: Runs | I1: Balls | J1: Average | K1: Strike Rate | L1: 100s | M1: 50s | N1: 4s | O1: 6s | P1: Not Outs | Q1: Bowling Matches | R1: Overs | S1: Runs Conceded | T1: Wickets | U1: Economy | V1: Maidens | W1: Bowling Average | X1: Cost Per Run | Y1: Cost Per Wicket | Z1: Boundary Percentage | AA1: Opener_Score | AB1: Middle_Order_Score | AC1: Finisher_Score | AD1: AR_Score | AE1: Bowler_Score | AF1: Eligible_Finisher
A2: Ruturaj Gaikwad | B2: CSK | C2: Retained | D2: Anchor | E2: 0 | F2: Ruturaj_Gaikwad_CSK | G2: 14 | H2: 337 | I2: 273 | J2: 28.08 | K2: 123.44 | L2: 0 | M2: 2 | N2: 29 | O2: 12 | P2: 2 | Q2: 0 | R2: 0 | S2: 0 | T2: 0 | U2: 0 | V2: 0 | W2: 0 | X2: 0 | Y2: 0 | Z2: 0.12166172 | AA2: 415.9928 | AB2: 79.62 | AC2: 65.726 | AD2: 129.788 | AE2: 0 | AF2: NO | AI2: Role | AJ2: Anchor
A3: MS Dhoni | B3: CSK | C3: Retained | D3: Wicketkeeper | E3: 0 | F3: MS_Dhoni_CSK | G3: 0 | H3: 0 | I3: 0 | J3: 0 | K3: 0 | L3: 0 | M3: 0 | N3: 0 | O3: 0 | P3: 0 | Q3: 0 | R3: 0 | S3: 0 | T3: 0 | U3: 0 | V3: 0 | W3: 0 | X3: 0 | Y3: 0 | Z3: 0 | AA3: 0 | AB3: 0 | AC3: 0 | AD3: 0 | AE3: 0 | AF3: NO | AN3: Role | AO3: All-Rounder
A4: Dewald Brevis | B4: CSK | C4: Retained | D4: Anchor | E4: 0 | F4: Dewald_Brevis_CSK | G4: 11 | H4: 151 | I4: 118 | J4: 18.87 | K4: 127.96 | L4: 0 | M4: 0 | N4: 8 | O4: 10 | P4: 0 | Q4: 0 | R4: 0 | S4: 0 | T4: 0 | U4: 0 | V4: 0 | W4: 0 | X4: 0 | Y4: 0 | Z4: 0.1192053 | AA4: 193.2196 | AB4: 48.24 | AC4: 65.284 | AD4: 70.892 | AE4: 0 | AF4: NO | AI4: Row Labels | AJ4: Sum of Opener_Score
A5: Akash Madhwal | B5: CSK | C5: Replacement for Ayush Mhatre | D5: Pacer | E5: 0.3 | F5: Akash_Madhwal_CSK | G5: 0 | H5: 0 | I5: 0 | J5: 0 | K5: 0 | L5: 0 | M5: 0 | N5: 0 | O5: 0 | P5: 0 | Q5: 0 | R5: 0 | S5: 0 | T5: 0 | U5: 0 | V5: 0 | W5: 0 | X5: 0 | Y5: 0 | Z5: 0 | AA5: 0 | AB5: 0 | AC5: 0 | AD5: 0 | AE5: 0 | AF5: NO | AI5: Shubman Gill | AJ5: 1193.3064 | AN5: Row Labels | AO5: Sum of AR_Score
A6: Urvil Patel | B6: CSK | C6: Retained | D6: Wicketkeeper | E6: 0 | F6: Urvil_Patel_CSK | G6: 0 | H6: 0 | I6: 0 | J6: 0 | K6: 0 | L6: 0 | M6: 0 | N6: 0 | O6: 0 | P6: 0 | Q6: 0 | R6: 0 | S6: 0 | T6: 0 | U6: 0 | V6: 0 | W6: 0 | X6: 0 | Y6: 0 | Z6: 0 | AA6: 0 | AB6: 0 | AC6: 0 | AD6: 0 | AE6: 0 | AF6: NO | AI6: Vaibhav Suryavanshi | AJ6: 1841.448 | AN6: Abhishek Sharma | AO6: 211.844
A7: Anshul Kamboj | B7: CSK | C7: Retained | D7: All-Rounder | E7: 0 | F7: Anshul_Kamboj_CSK | G7: 14 | H7: 58 | I7: 38 | J7: 29 | K7: 152.63 | L7: 0 | M7: 0 | N7: 3 | O7: 4 | P7: 2 | Q7: 14 | R7: 50.2 | S7: 530 | T7: 21 | U7: 10.52 | V7: 0 | W7: 25.23 | X7: 0 | Y7: 0 | Z7: 0.12068966 | AA7: 88.5254 | AB7: 57.926 | AC7: 73.152 | AD7: 198.886 | AE7: 199.48 | AF7: YES | AI7: Grand Total | AJ7: 3034.7544 | AN7: Anshul Kamboj | AO7: 198.886
A8: Dian Forrester | B8: CSK | C8: Replacement for Jamie Overton | D8: All-Rounder | E8: 0.75 | F8: Dian_Forrester_CSK | G8: 0 | H8: 0 | I8: 0 | J8: 0 | K8: 0 | L8: 0 | M8: 0 | N8: 0 | O8: 0 | P8: 0 | Q8: 0 | R8: 0 | S8: 0 | T8: 0 | U8: 0 | V8: 0 | W8: 0 | X8: 0 | Y8: 0 | Z8: 0 | AA8: 0 | AB8: 0 | AC8: 0 | AD8: 0 | AE8: 0 | AF8: NO | AN8: Hardik Pandya | AO8: 198.14
A9: Macneil Noronha | B9: CSK | C9: Replacement for Ramakrishna Ghosh | D9: All-Rounder | E9: 0.3 | F9: Macneil_Noronha_CSK | G9: 0 | H9: 0 | I9: 0 | J9: 0 | K9: 0 | L9: 0 | M9: 0 | N9: 0 | O9: 0 | P9: 0 | Q9: 0 | R9: 0 | S9: 0 | T9: 0 | U9: 0 | V9: 0 | W9: 0 | X9: 0 | Y9: 0 | Z9: 0 | AA9: 0 | AB9: 0 | AC9: 0 | AD9: 0 | AE9: 0 | AF9: NO | AN9: Grand Total | AO9: 608.87
A10: Shivam Dube | B10: CSK | C10: Retained | D10: All-Rounder | E10: 0 | F10: Shivam_Dube_CSK | G10: 13 | H10: 270 | I10: 170 | J10: 38.57 | K10: 158.82 | L10: 0 | M10: 0 | N10: 24 | O10: 15 | P10: 5 | Q10: 0 | R10: 0 | S10: 0 | T10: 0 | U10: 0 | V10: 0 | W10: 0 | X10: 0 | Y10: 0 | Z10: 0.14444444 | AA10: 428.814 | AB10: 99.192 | AC10: 100.028 | AD10: 122.764 | AE10: 0 | AF10: YES
A11: Kuldip Yadav | B11: CSK | C11: Replacement for Khaleel Ahmed | D11: Pacer | E11: 0.3 | F11: Kuldip_Yadav_CSK | G11: 0 | H11: 0 | I11: 0 | J11: 0 | K11: 0 | L11: 0 | M11: 0 | N11: 0 | O11: 0 | P11: 0 | Q11: 0 | R11: 0 | S11: 0 | T11: 0 | U11: 0 | V11: 0 | W11: 0 | X11: 0 | Y11: 0 | Z11: 0 | AA11: 0 | AB11: 0 | AC11: 0 | AD11: 0 | AE11: 0 | AF11: NO | AI11: Role | AJ11: (Multiple Items)
A12: Noor Ahmad | B12: CSK | C12: Retained | D12: Spinner | E12: 0 | F12: Noor_Ahmad_CSK | G12: 14 | H12: 11 | I12: 23 | J12: 3.66 | K12: 47.82 | L12: 0 | M12: 0 | N12: 0 | O12: 1 | P12: 1 | Q12: 14 | R12: 51 | S12: 428 | T12: 13 | U12: 8.39 | V12: 0 | W12: 32.92 | X12: 0 | Y12: 0 | Z12: 0.090909091 | AA12: 5.2602 | AB12: 17.128 | AC12: 22.978 | AD12: 102.084 | AE12: 121.61 | AF12: NO | AN12: Role | AO12: (Multiple Items)
A13: Mukesh Choudhary | B13: CSK | C13: Retained | D13: Pacer | E13: 0 | F13: Mukesh_Choudhary_CSK | G13: 0 | H13: 0 | I13: 0 | J13: 0 | K13: 0 | L13: 0 | M13: 0 | N13: 0 | O13: 0 | P13: 0 | Q13: 8 | R13: 28 | S13: 249 | T13: 8 | U13: 8.89 | V13: 0 | W13: 31.12 | X13: 0 | Y13: 0 | Z13: 0 | AA13: 0 | AB13: 0 | AC13: 0 | AD13: 46.22 | AE13: 71.11 | AF13: NO | AI13: Row Labels | AJ13: Sum of Middle_Order_Score
A14: Spencer Johnson | B14: CSK | C14: Replacement for Nathan Ellis | D14: Pacer | E14: 1.5 | F14: Spencer_Johnson_CSK | G14: 0 | H14: 0 | I14: 0 | J14: 0 | K14: 0 | L14: 0 | M14: 0 | N14: 0 | O14: 0 | P14: 0 | Q14: 0 | R14: 0 | S14: 0 | T14: 0 | U14: 0 | V14: 0 | W14: 0 | X14: 0 | Y14: 0 | Z14: 0 | AA14: 0 | AB14: 0 | AC14: 0 | AD14: 0 | AE14: 0 | AF14: NO | AI14: Abhishek Sharma | AJ14: 4634.4984 | AN14: Row Labels | AO14: Sum of Bowler_Score
A15: Shreyas Gopal | B15: CSK | C15: Retained | D15: Spinner | E15: 0 | F15: Shreyas_Gopal_CSK | G15: 0 | H15: 0 | I15: 0 | J15: 0 | K15: 0 | L15: 0 | M15: 0 | N15: 0 | O15: 0 | P15: 0 | Q15: 0 | R15: 0 | S15: 0 | T15: 0 | U15: 0 | V15: 0 | W15: 0 | X15: 0 | Y15: 0 | Z15: 0 | AA15: 0 | AB15: 0 | AC15: 0 | AD15: 0 | AE15: 0 | AF15: NO | AI15: Heinrich Klaasen | AJ15: 4792.32 | AN15: Arshdeep Singh | AO15: 129.8
A16: Gurjapneet Singh | B16: CSK | C16: Retained | D16: Pacer | E16: 0 | F16: Gurjapneet_Singh_CSK | G16: 0 | H16: 0 | I16: 0 | J16: 0 | K16: 0 | L16: 0 | M16: 0 | N16: 0 | O16: 0 | P16: 0 | Q16: 8 | R16: 25.1 | S16: 233 | T16: 4 | U16: 9.25 | V16: 0 | W16: 58.25 | X16: 0 | Y16: 0 | Z16: 0 | AA16: 0 | AB16: 0 | AC16: 0 | AD16: 13.5 | AE16: 30.75 | AF16: NO | AI16: KL Rahul | AJ16: 4717.2202 | AN16: Brijesh Sharma | AO16: 130.11
A17: Sanju Samson | B17: CSK | C17: Trade | D17: Wicketkeeper | E17: 0 | F17: Sanju_Samson_CSK | G17: 14 | H17: 477 | I17: 288 | J17: 43.36 | K17: 165.62 | L17: 2 | M17: 1 | N17: 53 | O17: 24 | P17: 3 | Q17: 0 | R17: 0 | S17: 0 | T17: 0 | U17: 0 | V17: 0 | W17: 0 | X17: 0 | Y17: 0 | Z17: 0.16142558 | AA17: 790.0074 | AB17: 113.168 | AC17: 108.848 | AD17: 182.224 | AE17: 0 | AF17: NO | AI17: Grand Total | AJ17: 14144.039 | AN17: Eshan Malinga | AO17: 190.67
A18: Akeal Hosein | B18: CSK | C18: Auction | D18: Pacer | E18: 2 | F18: Akeal_Hosein_CSK | G18: 7 | H18: 5 | I18: 3 | J18: - | K18: 166.66 | L18: 0 | M18: 0 | N18: 0 | O18: 0 | P18: 3 | Q18: 7 | R18: 24.4 | S18: 198 | T18: 8 | U18: 8.02 | V18: 1 | W18: 24.75 | X18: 0.4 | Y18: 0.25 | Z18: 0 | AA18: 8.333 | AB18: #VALUE! | AC18: 75.514 | AD18: 88.792 | AE18: 71.98 | AF18: NO | AN18: Jofra Archer | AO18: 240.69
A19: Prashant Veer | B19: CSK | C19: Auction | D19: All-Rounder | E19: 14.2 | F19: Prashant_Veer_CSK | G19: 6 | H19: 90 | I19: 67 | J19: 45 | K19: 134.32 | L19: 0 | M19: 0 | N19: 10 | O19: 3 | P19: 3 | Q19: 0 | R19: 0 | S19: 0 | T19: 0 | U19: 0 | V19: 0 | W19: 0 | X19: 0.15777778 | Y19: 0 | Z19: 0.14444444 | AA19: 120.888 | AB19: 68.864 | AC19: 65.378 | AD19: 59.864 | AE19: 0 | AF19: NO | AN19: Josh Hazlewood | AO19: 140.41
A20: Kartik Sharma | B20: CSK | C20: Auction | D20: Wicketkeeper | E20: 14.2 | F20: Kartik_Sharma_CSK | G20: 11 | H20: 295 | I20: 216 | J20: 32.77 | K20: 136.57 | L20: 0 | M20: 2 | N20: 24 | O20: 16 | P20: 2 | Q20: 0 | R20: 0 | S20: 0 | T20: 0 | U20: 0 | V20: 0 | W20: 0 | X20: 0.048135593 | Y20: 0 | Z20: 0.13559322 | AA20: 402.8815 | AB20: 79.922 | AC20: 81.828 | AD20: 119.814 | AE20: 0 | AF20: NO | AN20: Kagiso Rabada | AO20: 280.32
A21: Matthew Short | B21: CSK | C21: Auction | D21: All-Rounder | E21: 1.5 | F21: Matthew_Short_CSK | G21: 3 | H21: 60 | I21: 51 | J21: 20 | K21: 117.64 | L21: 0 | M21: 0 | N21: 6 | O21: 1 | P21: 0 | Q21: 0 | R21: 0 | S21: 0 | T21: 0 | U21: 0 | V21: 0 | W21: 0 | X21: 0.025 | Y21: 0 | Z21: 0.11666667 | AA21: 70.584 | AB21: 37.528 | AC21: 46.506 | AD21: 41.528 | AE21: 0 | AF21: NO | AN21: Kartik Tyagi | AO21: 170.24
A22: Aman Khan | B22: CSK | C22: Auction | D22: All-Rounder | E22: 0.4 | F22: Aman_Khan_CSK | G22: 0 | H22: 0 | I22: 0 | J22: 0 | K22: 0 | L22: 0 | M22: 0 | N22: 0 | O22: 0 | P22: 0 | Q22: 0 | R22: 0 | S22: 0 | T22: 0 | U22: 0 | V22: 0 | W22: 0 | X22: 0 | Y22: 0 | Z22: 0 | AA22: 0 | AB22: 0 | AC22: 0 | AD22: 0 | AE22: 0 | AF22: NO | AN22: Lungi Ngidi | AO22: 121.78
A23: Sarfaraz Khan | B23: CSK | C23: Auction | D23: Anchor | E23: 0.75 | F23: Sarfaraz_Khan_CSK | G23: 0 | H23: 0 | I23: 0 | J23: 0 | K23: 0 | L23: 0 | M23: 0 | N23: 0 | O23: 0 | P23: 0 | Q23: 0 | R23: 0 | S23: 0 | T23: 0 | U23: 0 | V23: 0 | W23: 0 | X23: 0 | Y23: 0 | Z23: 0 | AA23: 0 | AB23: 0 | AC23: 0 | AD23: 0 | AE23: 0 | AF23: NO | AN23: Mohammed Siraj | AO23: 180.94
A24: Rahul Chahar | B24: CSK | C24: Auction | D24: Spinner | E24: 1 | F24: Rahul_Chahar_CSK | G24: 0 | H24: 0 | I24: 0 | J24: 0 | K24: 0 | L24: 0 | M24: 0 | N24: 0 | O24: 0 | P24: 0 | Q24: 0 | R24: 0 | S24: 0 | T24: 0 | U24: 0 | V24: 0 | W24: 0 | X24: 0 | Y24: 0 | Z24: 0 | AA24: 0 | AB24: 0 | AC24: 0 | AD24: 0 | AE24: 0 | AF24: NO | AN24: Praful Hinge | AO24: 128.27
A25: Matt Henry | B25: CSK | C25: Auction | D25: Pacer | E25: 2 | F25: Matt_Henry_CSK | G25: 0 | H25: 0 | I25: 0 | J25: 0 | K25: 0 | L25: 0 | M25: 0 | N25: 0 | O25: 0 | P25: 0 | Q25: 0 | R25: 0 | S25: 0 | T25: 0 | U25: 0 | V25: 0 | W25: 0 | X25: 0 | Y25: 0 | Z25: 0 | AA25: 0 | AB25: 0 | AC25: 0 | AD25: 0 | AE25: 0 | AF25: NO | AN25: Prasidh Krishna | AO25: 149.57
A26: Zak Foulkes | B26: CSK | C26: Auction | D26: All-Rounder | E26: 0.75 | F26: Zak_Foulkes_CSK | G26: 0 | H26: 0 | I26: 0 | J26: 0 | K26: 0 | L26: 0 | M26: 0 | N26: 0 | O26: 0 | P26: 0 | Q26: 0 | R26: 0 | S26: 0 | T26: 0 | U26: 0 | V26: 0 | W26: 0 | X26: 0 | Y26: 0 | Z26: 0 | AA26: 0 | AB26: 0 | AC26: 0 | AD26: 0 | AE26: 0 | AF26: NO | AN26: Prince Yadav | AO26: 151.18
A27: KL Rahul | B27: DC | C27: Retained | D27: Wicketkeeper | E27: 0 | F27: KL_Rahul_DC | G27: 14 | H27: 593 | I27: 340 | J27: 45.61 | K27: 174.41 | L27: 1 | M27: 5 | N27: 56 | O27: 31 | P27: 1 | Q27: 0 | R27: 0 | S27: 0 | T27: 0 | U27: 0 | V27: 0 | W27: 0 | X27: 0 | Y27: 0 | Z27: 0.14671164 | AA27: 1034.2513 | AB27: 117.426 | AC27: 117.764 | AD27: 214.782 | AE27: 0 | AF27: NO | AI27: Eligible_Finisher | AJ27: YES | AN27: Rashid Khan | AO27: 200.93
A28: Karun Nair | B28: DC | C28: Retained | D28: Anchor | E28: 0 | F28: Karun_Nair_DC | G28: 2 | H28: 18 | I28: 18 | J28: 9 | K28: 100 | L28: 0 | M28: 0 | N28: 3 | O28: 0 | P28: 0 | Q28: 0 | R28: 0 | S28: 0 | T28: 0 | U28: 0 | V28: 0 | W28: 0 | X28: 0 | Y28: 0 | Z28: 0.16666667 | AA28: 18 | AB28: 25.4 | AC28: 39.1 | AD28: 25.4 | AE28: 0 | AF28: NO | AN28: Rasikh Salam | AO28: 180.55
A29: Abishek Porel | B29: DC | C29: Retained | D29: Wicketkeeper | E29: 0 | F29: Abishek_Porel_DC | G29: 4 | H29: 108 | I29: 88 | J29: 27 | K29: 122.72 | L29: 0 | M29: 1 | N29: 15 | O29: 1 | P29: 0 | Q29: 0 | R29: 0 | S29: 0 | T29: 0 | U29: 0 | V29: 0 | W29: 0 | X29: 0 | Y29: 0 | Z29: 0.14814815 | AA29: 132.5376 | AB29: 46.144 | AC29: 46.688 | AD29: 56.944 | AE29: 0 | AF29: NO | AI29: Row Labels | AJ29: Sum of Finisher_Score | AN29: Sakib Hussain | AO29: 140.55
A30: Tristan Stubbs | B30: DC | C30: Retained | D30: Anchor | E30: 0 | F30: Tristan_Stubbs_DC | G30: 14 | H30: 275 | I30: 216 | J30: 34.37 | K30: 127.31 | L30: 0 | M30: 2 | N30: 18 | O30: 9 | P30: 5 | Q30: 0 | R30: 0 | S30: 0 | T30: 0 | U30: 0 | V30: 0 | W30: 0 | X30: 0 | Y30: 0 | Z30: 0.098181818 | AA30: 350.1025 | AB30: 91.71 | AC30: 73.124 | AD30: 117.962 | AE30: 0 | AF30: NO | AI30: Finn Allen | AJ30: 136.494 | AN30: Grand Total | AO30: 2536.01
A31: Axar Patel | B31: DC | C31: Retained | D31: All-Rounder | E31: 0 | F31: Axar_Patel_DC | G31: 14 | H31: 173 | I31: 132 | J31: 19.22 | K31: 131.06 | L31: 0 | M31: 1 | N31: 16 | O31: 6 | P31: 2 | Q31: 14 | R31: 44 | S31: 360 | T31: 11 | U31: 8.18 | V31: 0 | W31: 32.72 | X31: 0 | Y31: 0 | Z31: 0.12716763 | AA31: 226.7338 | AB31: 61.2 | AC31: 63.824 | AD31: 153.752 | AE31: 101.82 | AF31: NO | AI31: Nitish Kumar Reddy | AJ31: 110.836
A32: Sameer Rizvi | B32: DC | C32: Retained | D32: Anchor | E32: 0 | F32: Sameer_Rizvi_DC | G32: 11 | H32: 252 | I32: 171 | J32: 36 | K32: 147.36 | L32: 0 | M32: 2 | N32: 15 | O32: 17 | P32: 2 | Q32: 0 | R32: 0 | S32: 0 | T32: 0 | U32: 0 | V32: 0 | W32: 0 | X32: 0 | Y32: 0 | Z32: 0.12698413 | AA32: 371.3472 | AB32: 79.072 | AC32: 90.394 | AD32: 109.072 | AE32: 0 | AF32: NO | AI32: Priyansh Arya | AJ32: 140.048
A33: Ashutosh Sharma | B33: DC | C33: Retained | D33: Anchor | E33: 0 | F33: Ashutosh_Sharma_DC | G33: 0 | H33: 0 | I33: 0 | J33: 0 | K33: 0 | L33: 0 | M33: 0 | N33: 0 | O33: 0 | P33: 0 | Q33: 0 | R33: 0 | S33: 0 | T33: 0 | U33: 0 | V33: 0 | W33: 0 | X33: 0 | Y33: 0 | Z33: 0 | AA33: 0 | AB33: 0 | AC33: 0 | AD33: 0 | AE33: 0 | AF33: NO | AI33: Grand Total | AJ33: 387.378
A34: Vipraj Nigam | B34: DC | C34: Retained | D34: All-Rounder | E34: 0 | F34: Vipraj_Nigam_DC | G34: 5 | H34: 15 | I34: 10 | J34: 15 | K34: 150 | L34: 0 | M34: 0 | N34: 2 | O34: 0 | P34: 1 | Q34: 5 | R34: 9 | S34: 113 | T34: 2 | U34: 12.55 | V34: 0 | W34: 56.5 | X34: 0 | Y34: 0 | Z34: 0.13333333 | AA34: 22.5 | AB34: 42.5 | AC34: 62.5 | AD34: 27.4 | AE34: 7.45 | AF34: NO
A35: Ajay Mandal | B35: DC | C35: Retained | D35: All-Rounder | E35: 0 | F35: Ajay_Mandal_DC | G35: 0 | H35: 0 | I35: 0 | J35: 0 | K35: 0 | L35: 0 | M35: 0 | N35: 0 | O35: 0 | P35: 0 | Q35: 0 | R35: 0 | S35: 0 | T35: 0 | U35: 0 | V35: 0 | W35: 0 | X35: 0 | Y35: 0 | Z35: 0 | AA35: 0 | AB35: 0 | AC35: 0 | AD35: 0 | AE35: 0 | AF35: NO
A36: Tripurana Vijay | B36: DC | C36: Retained | D36: All-Rounder | E36: 0 | F36: Tripurana_Vijay_DC | G36: 0 | H36: 0 | I36: 0 | J36: 0 | K36: 0 | L36: 0 | M36: 0 | N36: 0 | O36: 0 | P36: 0 | Q36: 0 | R36: 0 | S36: 0 | T36: 0 | U36: 0 | V36: 0 | W36: 0 | X36: 0 | Y36: 0 | Z36: 0 | AA36: 0 | AB36: 0 | AC36: 0 | AD36: 0 | AE36: 0 | AF36: NO
A37: Madhav Tiwari | B37: DC | C37: Retained | D37: All-Rounder | E37: 0 | F37: Madhav_Tiwari_DC | G37: 0 | H37: 0 | I37: 0 | J37: 0 | K37: 0 | L37: 0 | M37: 0 | N37: 0 | O37: 0 | P37: 0 | Q37: 3 | R37: 10 | S37: 87 | T37: 4 | U37: 8.7 | V37: 0 | W37: 21.75 | X37: 0 | Y37: 0 | Z37: 0 | AA37: 0 | AB37: 0 | AC37: 0 | AD37: 14.6 | AE37: 31.3 | AF37: NO
A38: Mitchell Starc | B38: DC | C38: Retained | D38: Pacer | E38: 0 | F38: Mitchell_Starc_DC | G38: 0 | H38: 0 | I38: 0 | J38: 0 | K38: 0 | L38: 0 | M38: 0 | N38: 0 | O38: 0 | P38: 0 | Q38: 6 | R38: 22 | S38: 224 | T38: 11 | U38: 10.18 | V38: 0 | W38: 20.36 | X38: 0 | Y38: 0 | Z38: 0 | AA38: 0 | AB38: 0 | AC38: 0 | AD38: 67.64 | AE38: 99.82 | AF38: NO
A39: T Natarajan | B39: DC | C39: Retained | D39: Pacer | E39: 0 | F39: T_Natarajan_DC | G39: 0 | H39: 0 | I39: 0 | J39: 0 | K39: 0 | L39: 0 | M39: 0 | N39: 0 | O39: 0 | P39: 0 | Q39: 10 | R39: 31.5 | S39: 356 | T39: 5 | U39: 11.18 | V39: 0 | W39: 71.2 | X39: 0 | Y39: 0 | Z39: 0 | AA39: 0 | AB39: 0 | AC39: 0 | AD39: 17.64 | AE39: 38.82 | AF39: NO
A40: Mukesh Kumar | B40: DC | C40: Retained | D40: Pacer | E40: 0 | F40: Mukesh_Kumar_DC | G40: 0 | H40: 0 | I40: 0 | J40: 0 | K40: 0 | L40: 0 | M40: 0 | N40: 0 | O40: 0 | P40: 0 | Q40: 10 | R40: 31.2 | S40: 353 | T40: 6 | U40: 11.26 | V40: 0 | W40: 58.83 | X40: 0 | Y40: 0 | Z40: 0 | AA40: 0 | AB40: 0 | AC40: 0 | AD40: 25.48 | AE40: 48.74 | AF40: NO
...

Sheet Master_Batsman_Analysis
A1: Player | B1: Team | C1: Role | D1: Price | E1: Matches | F1: Runs | G1: Balls | H1: Average | I1: Strike Rate | J1: 100s | K1: 50s | L1: 4s | M1: 6s | N1: Not Outs | O1: Cost Per Run | P1: Boundary Percentage | Q1: Batting_Impact | R1: Consistency Score | S1: Aggression Score | T1: Value Score | U1: Overprice Score | V1: Key
A2: Vishnu Vinod | B2: PBKS | C2: Wicketkeeper | D2: 0 | E2: 1 | F2: 15 | G2: 8 | H2: - | I2: 187.5 | J2: 0 | K2: 0 | L2: 1 | M2: 1 | N2: 1 | O2: 0 | P2: 0.13333333 | Q2: #VALUE! | R2: #VALUE! | S2: 25 | T2: 0 | U2: #VALUE! | V2: Vishnu Vinod_PBKS
A3: Vaibhav Suryavanshi | B3: RR | C3: Anchor | D3: 0 | E3: 16 | F3: 776 | G3: 327 | H3: 48.5 | I3: 237.3 | J3: 1 | K3: 5 | L3: 63 | M3: 72 | N3: 0 | O3: 0 | P3: 0.17396907 | Q3: 8931.0228 | R3: 776 | S3: 41.282861 | T3: 0 | U3: 0 | V3: Vaibhav Suryavanshi_RR | AB3: Role | AC3: Wicketkeeper
A4: Kartik Sharma | B4: CSK | C4: Wicketkeeper | D4: 14.2 | E4: 11 | F4: 295 | G4: 216 | H4: 32.77 | I4: 136.57 | J4: 0 | K4: 2 | L4: 24 | M4: 16 | N4: 2 | O4: 0.048135593 | P4: 0.13559322 | Q4: 1320.2427 | R4: 360.47 | S4: 18.517966 | T4: 92.974836 | U4: 0.010755598 | V4: Kartik Sharma_CSK
A5: Akash Madhwal | B5: CSK | C5: Pacer | D5: 0.3 | E5: 0 | F5: 0 | G5: 0 | H5: 0 | I5: 0 | J5: 0 | K5: 0 | L5: 0 | M5: 0 | N5: 0 | O5: 0 | P5: 0 | Q5: 0 | Y5: Row Labels | Z5: Sum of Batting_Impact | AB5: Row Labels | AC5: Sum of Strike Rate
A6: Mukul Choudhary | B6: LSG | C6: Wicketkeeper | D6: 2.6 | E6: 10 | F6: 170 | G6: 120 | H6: 28.33 | I6: 141.66 | J6: 0 | K6: 1 | L6: 11 | M6: 12 | N6: 4 | O6: 0.015294118 | P6: 0.13529412 | Q6: 682.24873 | R6: 283.3 | S6: 19.165765 | T6: 262.40336 | U6: 0.0038109269 | V6: Mukul Choudhary_LSG | Y6: Shubman Gill | Z6: 5459.3768 | AB6: Finn Allen | AC6: 214.11
A7: Anshul Kamboj | B7: CSK | C7: All-Rounder | D7: 0 | E7: 14 | F7: 58 | G7: 38 | H7: 29 | I7: 152.63 | J7: 0 | K7: 0 | L7: 3 | M7: 4 | N7: 2 | O7: 0 | P7: 0.12068966 | Q7: 256.72366 | Y7: Vaibhav Suryavanshi | Z7: 8931.0228 | AB7: Ryan Rickelton | AC7: 186.66
A8: Dian Forrester | B8: CSK | C8: All-Rounder | D8: 0.75 | E8: 0 | F8: 0 | G8: 0 | H8: 0 | I8: 0 | J8: 0 | K8: 0 | L8: 0 | M8: 0 | N8: 0 | O8: 0 | P8: 0 | Q8: 0 | Y8: Virat Kohli | Z8: 6296.7375 | AB8: Vishnu Vinod | AC8: 187.5
A9: Macneil Noronha | B9: CSK | C9: All-Rounder | D9: 0.3 | E9: 0 | F9: 0 | G9: 0 | H9: 0 | I9: 0 | J9: 0 | K9: 0 | L9: 0 | M9: 0 | N9: 0 | O9: 0 | P9: 0 | Q9: 0 | Y9: Grand Total | Z9: 20687.137 | AB9: Grand Total | AC9: 588.27
A10: Shivam Dube | B10: CSK | C10: All-Rounder | D10: 0 | E10: 13 | F10: 270 | G10: 170 | H10: 38.57 | I10: 158.82 | J10: 0 | K10: 0 | L10: 24 | M10: 15 | N10: 5 | O10: 0 | P10: 0.14444444 | Q10: 1653.9356
A11: Kuldip Yadav | B11: CSK | C11: Pacer | D11: 0.3 | E11: 0 | F11: 0 | G11: 0 | H11: 0 | I11: 0 | J11: 0 | K11: 0 | L11: 0 | M11: 0 | N11: 0 | O11: 0 | P11: 0 | Q11: 0
A12: Noor Ahmad | B12: CSK | C12: Spinner | D12: 0 | E12: 14 | F12: 11 | G12: 23 | H12: 3.66 | I12: 47.82 | J12: 0 | K12: 0 | L12: 0 | M12: 1 | N12: 1 | O12: 0 | P12: 0.090909091 | Q12: 1.9252332
A13: Mukesh Choudhary | B13: CSK | C13: Pacer | D13: 0 | E13: 0 | F13: 0 | G13: 0 | H13: 0 | I13: 0 | J13: 0 | K13: 0 | L13: 0 | M13: 0 | N13: 0 | O13: 0 | P13: 0 | Q13: 0
A14: Spencer Johnson | B14: CSK | C14: Pacer | D14: 1.5 | E14: 0 | F14: 0 | G14: 0 | H14: 0 | I14: 0 | J14: 0 | K14: 0 | L14: 0 | M14: 0 | N14: 0 | O14: 0 | P14: 0 | Q14: 0
A15: Shreyas Gopal | B15: CSK | C15: Spinner | D15: 0 | E15: 0 | F15: 0 | G15: 0 | H15: 0 | I15: 0 | J15: 0 | K15: 0 | L15: 0 | M15: 0 | N15: 0 | O15: 0 | P15: 0 | Q15: 0 | Y15: Row Labels | Z15: Sum of Strike Rate | AA15: Sum of Boundary Percentage
A16: Gurjapneet Singh | B16: CSK | C16: Pacer | D16: 0 | E16: 0 | F16: 0 | G16: 0 | H16: 0 | I16: 0 | J16: 0 | K16: 0 | L16: 0 | M16: 0 | N16: 0 | O16: 0 | P16: 0 | Q16: 0 | Y16: Finn Allen | Z16: 214.11 | AA16: 0.1747851
A17: Virat Kohli | B17: RCB | C17: Anchor | D17: 0 | E17: 16 | F17: 675 | G17: 407 | H17: 56.25 | I17: 165.84 | J17: 1 | K17: 5 | L17: 73 | M17: 25 | N17: 4 | O17: 0 | P17: 0.14518519 | Q17: 6296.7375 | R17: 900 | S17: 24.077511 | T17: 0 | U17: 0 | V17: Virat Kohli_RCB | Y17: Priyansh Arya | Z17: 211.62 | AA17: 0.16208791
A18: Akeal Hosein | B18: CSK | C18: Pacer | D18: 2 | E18: 7 | F18: 5 | G18: 3 | H18: - | I18: 166.66 | J18: 0 | K18: 0 | L18: 0 | M18: 0 | N18: 3 | O18: 0.4 | P18: 0 | Q18: #VALUE! | Y18: Vaibhav Suryavanshi | Z18: 237.3 | AA18: 0.17396907
A19: Prashant Veer | B19: CSK | C19: All-Rounder | D19: 14.2 | E19: 6 | F19: 90 | G19: 67 | H19: 45 | I19: 134.32 | J19: 0 | K19: 0 | L19: 10 | M19: 3 | N19: 3 | O19: 0.15777778 | P19: 0.14444444 | Q19: 543.996 | Y19: Grand Total | Z19: 663.03 | AA19: 0.51084208
A20: Finn Allen | B20: KKR | C20: Wicketkeeper | D20: 2 | E20: 11 | F20: 349 | G20: 163 | H20: 34.9 | I20: 214.11 | J20: 1 | K20: 1 | L20: 33 | M20: 28 | N20: 1 | O20: 0.005730659 | P20: 0.1747851 | Q20: 2607.8812 | R20: 383.9 | S20: 37.423238 | T20: 1303.9406 | U20: 0.0007669061 | V20: Finn Allen_KKR
A21: Matthew Short | B21: CSK | C21: All-Rounder | D21: 1.5 | E21: 3 | F21: 60 | G21: 51 | H21: 20 | I21: 117.64 | J21: 0 | K21: 0 | L21: 6 | M21: 1 | N21: 0 | O21: 0.025 | P21: 0.11666667 | Q21: 141.168
A22: Aman Khan | B22: CSK | C22: All-Rounder | D22: 0.4 | E22: 0 | F22: 0 | G22: 0 | H22: 0 | I22: 0 | J22: 0 | K22: 0 | L22: 0 | M22: 0 | N22: 0 | O22: 0 | P22: 0 | Q22: 0
A23: Shubman Gill | B23: GT | C23: Anchor | D23: 0 | E23: 16 | F23: 732 | G23: 449 | H23: 45.75 | I23: 163.02 | J23: 1 | K23: 6 | L23: 74 | M23: 33 | N23: 0 | O23: 0 | P23: 0.14617486 | Q23: 5459.3768 | R23: 732 | S23: 23.829426 | T23: 0 | U23: 0 | V23: Shubman Gill_GT
A24: Rahul Chahar | B24: CSK | C24: Spinner | D24: 1 | E24: 0 | F24: 0 | G24: 0 | H24: 0 | I24: 0 | J24: 0 | K24: 0 | L24: 0 | M24: 0 | N24: 0 | O24: 0 | P24: 0 | Q24: 0
A25: Matt Henry | B25: CSK | C25: Pacer | D25: 2 | E25: 0 | F25: 0 | G25: 0 | H25: 0 | I25: 0 | J25: 0 | K25: 0 | L25: 0 | M25: 0 | N25: 0 | O25: 0 | P25: 0 | Q25: 0
A26: Zak Foulkes | B26: CSK | C26: All-Rounder | D26: 0.75 | E26: 0 | F26: 0 | G26: 0 | H26: 0 | I26: 0 | J26: 0 | K26: 0 | L26: 0 | M26: 0 | N26: 0 | O26: 0 | P26: 0 | Q26: 0
A27: MS Dhoni | B27: CSK | C27: Wicketkeeper | D27: 0 | E27: 0 | F27: 0 | G27: 0 | H27: 0 | I27: 0 | J27: 0 | K27: 0 | L27: 0 | M27: 0 | N27: 0 | O27: 0 | P27: 0 | Q27: 0 | R27: 0 | S27: 0 | T27: 0 | U27: 0 | V27: MS Dhoni_CSK
A28: B Sai Sudharsan | B28: GT | C28: Anchor | D28: 0 | E28: 17 | F28: 722 | G28: 457 | H28: 45.12 | I28: 157.98 | J28: 1 | K28: 8 | L28: 75 | M28: 30 | N28: 1 | O28: 0 | P28: 0.14542936 | Q28: 5146.4576 | R28: 767.04 | S28: 22.974931 | T28: 0 | U28: 0 | V28: B Sai Sudharsan_GT
A29: Urvil Patel | B29: CSK | C29: Wicketkeeper | D29: 0 | E29: 0 | F29: 0 | G29: 0 | H29: 0 | I29: 0 | J29: 0 | K29: 0 | L29: 0 | M29: 0 | N29: 0 | O29: 0 | P29: 0 | Q29: 0 | R29: 0 | S29: 0 | T29: 0 | U29: 0 | V29: Urvil Patel_CSK
A30: Sanju Samson | B30: CSK | C30: Wicketkeeper | D30: 0 | E30: 14 | F30: 477 | G30: 288 | H30: 43.36 | I30: 165.62 | J30: 2 | K30: 1 | L30: 53 | M30: 24 | N30: 3 | O30: 0 | P30: 0.16142558 | Q30: 3425.4721 | R30: 607.04 | S30: 26.735304 | T30: 0 | U30: 0 | V30: Sanju Samson_CSK
A31: Axar Patel | B31: DC | C31: All-Rounder | D31: 0 | E31: 14 | F31: 173 | G31: 132 | H31: 19.22 | I31: 131.06 | J31: 0 | K31: 1 | L31: 16 | M31: 6 | N31: 2 | O31: 0 | P31: 0.12716763 | Q31: 435.78236
A32: Shreyas Iyer | B32: PBKS | C32: Anchor | D32: 0 | E32: 14 | F32: 498 | G32: 295 | H32: 55.33 | I32: 168.81 | J32: 1 | K32: 5 | L32: 39 | M32: 30 | N32: 4 | O32: 0 | P32: 0.13855422 | Q32: 4651.4481 | R32: 774.62 | S32: 23.389337 | T32: 0 | U32: 0 | V32: Shreyas Iyer_PBKS
A33: KL Rahul | B33: DC | C33: Wicketkeeper | D33: 0 | E33: 14 | F33: 593 | G33: 340 | H33: 45.61 | I33: 174.41 | J33: 1 | K33: 5 | L33: 56 | M33: 31 | N33: 1 | O33: 0 | P33: 0.14671164 | Q33: 4717.2202 | R33: 638.54 | S33: 25.587976 | T33: 0 | U33: 0 | V33: KL Rahul_DC
A34: Vipraj Nigam | B34: DC | C34: All-Rounder | D34: 0 | E34: 5 | F34: 15 | G34: 10 | H34: 15 | I34: 150 | J34: 0 | K34: 0 | L34: 2 | M34: 0 | N34: 1 | O34: 0 | P34: 0.13333333 | Q34: 33.75
A35: Ajay Mandal | B35: DC | C35: All-Rounder | D35: 0 | E35: 0 | F35: 0 | G35: 0 | H35: 0 | I35: 0 | J35: 0 | K35: 0 | L35: 0 | M35: 0 | N35: 0 | O35: 0 | P35: 0 | Q35: 0
A36: Tripurana Vijay | B36: DC | C36: All-Rounder | D36: 0 | E36: 0 | F36: 0 | G36: 0 | H36: 0 | I36: 0 | J36: 0 | K36: 0 | L36: 0 | M36: 0 | N36: 0 | O36: 0 | P36: 0 | Q36: 0
A37: Madhav Tiwari | B37: DC | C37: All-Rounder | D37: 0 | E37: 0 | F37: 0 | G37: 0 | H37: 0 | I37: 0 | J37: 0 | K37: 0 | L37: 0 | M37: 0 | N37: 0 | O37: 0 | P37: 0 | Q37: 0
A38: Mitchell Starc | B38: DC | C38: Pacer | D38: 0 | E38: 0 | F38: 0 | G38: 0 | H38: 0 | I38: 0 | J38: 0 | K38: 0 | L38: 0 | M38: 0 | N38: 0 | O38: 0 | P38: 0 | Q38: 0
A39: T Natarajan | B39: DC | C39: Pacer | D39: 0 | E39: 0 | F39: 0 | G39: 0 | H39: 0 | I39: 0 | J39: 0 | K39: 0 | L39: 0 | M39: 0 | N39: 0 | O39: 0 | P39: 0 | Q39: 0
A40: Mukesh Kumar | B40: DC | C40: Pacer | D40: 0 | E40: 0 | F40: 0 | G40: 0 | H40: 0 | I40: 0 | J40: 0 | K40: 0 | L40: 0 | M40: 0 | N40: 0 | O40: 0 | P40: 0 | Q40: 0
...

Sheet Master_Bowler_Analysis
A1: Player | B1: Team | C1: Role | D1: Bowling Matches | E1: Overs | F1: Runs Conceded | G1: Wickets | H1: Economy | I1: Maidens | J1: Bowling Average | K1: Cost Per Wicket | L1: Bowling Impact | M1: Wicket Efficiency | N1: Control Score | O1: Maiden Rate | P1: Adjusted Bowling Score | Q1: Final Professional Bowling Score | R1: key
A2: Ruturaj Gaikwad | B2: CSK | C2: Anchor | D2: 0 | E2: 0 | F2: 0 | G2: 0 | H2: 0 | I2: 0 | J2: 0 | K2: 0 | Q2: 0
A3: MS Dhoni | B3: CSK | C3: Wicketkeeper | D3: 0 | E3: 0 | F3: 0 | G3: 0 | H3: 0 | I3: 0 | J3: 0 | K3: 0 | Q3: 0
A4: Dewald Brevis | B4: CSK | C4: Anchor | D4: 0 | E4: 0 | F4: 0 | G4: 0 | H4: 0 | I4: 0 | J4: 0 | K4: 0 | Q4: 0 | U4: Row Labels | V4: Sum of Bowling Average
A5: Akash Madhwal | B5: CSK | C5: Pacer | D5: 0 | E5: 0 | F5: 0 | G5: 0 | H5: 0 | I5: 0 | J5: 0 | K5: 0 | L5: 0 | M5: 0 | N5: 0 | O5: 0 | P5: 0 | Q5: 0 | R5: Akash Madhwal_CSK | U5: Jasprit Bumrah | V5: 102.5
A6: Urvil Patel | B6: CSK | C6: Wicketkeeper | D6: 0 | E6: 0 | F6: 0 | G6: 0 | H6: 0 | I6: 0 | J6: 0 | K6: 0 | Q6: 0 | U6: Raghu Sharma | V6: 130
A7: Anshul Kamboj | B7: CSK | C7: All-Rounder | D7: 14 | E7: 50.2 | F7: 530 | G7: 21 | H7: 10.52 | I7: 0 | J7: 25.23 | K7: 25.238095 | Q7: 79.73 | U7: Trent Boult | V7: 94
A8: Dian Forrester | B8: CSK | C8: All-Rounder | D8: 0 | E8: 0 | F8: 0 | G8: 0 | H8: 0 | I8: 0 | J8: 0 | K8: 0 | Q8: 0 | U8: Grand Total | V8: 326.5
A9: Macneil Noronha | B9: CSK | C9: All-Rounder | D9: 0 | E9: 0 | F9: 0 | G9: 0 | H9: 0 | I9: 0 | J9: 0 | K9: 0 | Q9: 0
A10: Shivam Dube | B10: CSK | C10: All-Rounder | D10: 0 | E10: 0 | F10: 0 | G10: 0 | H10: 0 | I10: 0 | J10: 0 | K10: 0 | Q10: 0
A11: Kuldip Yadav | B11: CSK | C11: Pacer | D11: 0 | E11: 0 | F11: 0 | G11: 0 | H11: 0 | I11: 0 | J11: 0 | K11: 0 | L11: 0 | M11: 0 | N11: 0 | O11: 0 | P11: 0 | Q11: 0 | R11: Kuldip Yadav_CSK
A12: Noor Ahmad | B12: CSK | C12: Spinner | D12: 14 | E12: 51 | F12: 428 | G12: 13 | H12: 8.39 | I12: 0 | J12: 32.92 | K12: 32.923077 | L12: 0 | M12: 0 | N12: 0 | O12: 0 | P12: 0 | Q12: 28.3 | R12: Noor Ahmad_CSK
A13: Mukesh Choudhary | B13: CSK | C13: Pacer | D13: 8 | E13: 28 | F13: 249 | G13: 8 | H13: 8.89 | I13: 0 | J13: 31.12 | K13: 31.125 | L13: 0 | M13: 0 | N13: 0 | O13: 0 | P13: 0 | Q13: -0.9 | R13: Mukesh Choudhary_CSK | U13: Row Labels | V13: Sum of Final Professional Bowling Score
A14: Spencer Johnson | B14: CSK | C14: Pacer | D14: 0 | E14: 0 | F14: 0 | G14: 0 | H14: 0 | I14: 0 | J14: 0 | K14: 0 | L14: 0 | M14: 0 | N14: 0 | O14: 0 | P14: 0 | Q14: 0 | R14: Spencer Johnson_CSK | U14: Bhuvneshwar Kumar | V14: 136.32834
A15: Shreyas Gopal | B15: CSK | C15: Spinner | D15: 0 | E15: 0 | F15: 0 | G15: 0 | H15: 0 | I15: 0 | J15: 0 | K15: 0 | L15: 3.3131835 | M15: 0.92857143 | N15: 0.11918951 | O15: 0 | P15: 66.99 | Q15: 4.0718542 | R15: Shreyas Gopal_CSK | U15: Jofra Archer | V15: 109.02
A16: Gurjapneet Singh | B16: CSK | C16: Pacer | D16: 8 | E16: 25.1 | F16: 233 | G16: 4 | H16: 9.25 | I16: 0 | J16: 58.25 | K16: 58.25 | L16: 2.285347 | M16: 1 | N16: 0.11248594 | O16: 0 | P16: 7.09 | Q16: -48.412542 | R16: Gurjapneet Singh_CSK | U16: Kagiso Rabada | V16: 136.36242
A17: Sanju Samson | B17: CSK | C17: Wicketkeeper | D17: 0 | E17: 0 | F17: 0 | G17: 0 | H17: 0 | I17: 0 | J17: 0 | K17: 0 | Q17: 0 | U17: Grand Total | V17: 381.71076
A18: Akeal Hosein | B18: CSK | C18: Pacer | D18: 7 | E18: 24.4 | F18: 198 | G18: 8 | H18: 8.02 | I18: 1 | J18: 24.75 | K18: 24.75 | L18: 0 | M18: 0 | N18: 0 | O18: 0 | P18: 0 | Q18: 7.21 | R18: Akeal Hosein_CSK
A19: Prashant Veer | B19: CSK | C19: All-Rounder | D19: 0 | E19: 0 | F19: 0 | G19: 0 | H19: 0 | I19: 0 | J19: 0 | K19: 0 | Q19: 0
A20: Kartik Sharma | B20: CSK | C20: Wicketkeeper | D20: 0 | E20: 0 | F20: 0 | G20: 0 | H20: 0 | I20: 0 | J20: 0 | K20: 0 | Q20: 0
A21: Matthew Short | B21: CSK | C21: All-Rounder | D21: 0 | E21: 0 | F21: 0 | G21: 0 | H21: 0 | I21: 0 | J21: 0 | K21: 0 | Q21: 0
A22: Aman Khan | B22: CSK | C22: All-Rounder | D22: 0 | E22: 0 | F22: 0 | G22: 0 | H22: 0 | I22: 0 | J22: 0 | K22: 0 | Q22: 0
A23: Sarfaraz Khan | B23: CSK | C23: Anchor | D23: 0 | E23: 0 | F23: 0 | G23: 0 | H23: 0 | I23: 0 | J23: 0 | K23: 0 | Q23: 0
A24: Rahul Chahar | B24: CSK | C24: Spinner | D24: 0 | E24: 0 | F24: 0 | G24: 0 | H24: 0 | I24: 0 | J24: 0 | K24: 0 | L24: 0 | M24: 0 | N24: 0 | O24: 0 | P24: 0 | Q24: 0 | R24: Rahul Chahar_CSK
A25: Matt Henry | B25: CSK | C25: Pacer | D25: 3 | E25: 10 | F25: 130 | G25: 2 | H25: 13 | I25: 0 | J25: 65 | K25: 65 | L25: 0 | M25: 0 | N25: 0 | O25: 0 | P25: 0 | Q25: -79 | R25: Matt Henry_CSK
A26: Zak Foulkes | B26: CSK | C26: All-Rounder | D26: 0 | E26: 0 | F26: 0 | G26: 0 | H26: 0 | I26: 0 | J26: 0 | K26: 0 | Q26: 0
A27: KL Rahul | B27: DC | C27: Wicketkeeper | D27: 0 | E27: 0 | F27: 0 | G27: 0 | H27: 0 | I27: 0 | J27: 0 | K27: 0 | Q27: 0
A28: Karun Nair | B28: DC | C28: Anchor | D28: 0 | E28: 0 | F28: 0 | G28: 0 | H28: 0 | I28: 0 | J28: 0 | K28: 0 | Q28: 0
A29: Abishek Porel | B29: DC | C29: Wicketkeeper | D29: 0 | E29: 0 | F29: 0 | G29: 0 | H29: 0 | I29: 0 | J29: 0 | K29: 0 | Q29: 0
A30: Tristan Stubbs | B30: DC | C30: Anchor | D30: 0 | E30: 0 | F30: 0 | G30: 0 | H30: 0 | I30: 0 | J30: 0 | K30: 0 | Q30: 0
A31: Axar Patel | B31: DC | C31: All-Rounder | D31: 14 | E31: 44 | F31: 360 | G31: 11 | H31: 8.18 | I31: 0 | J31: 32.72 | K31: 32.727273 | Q31: 16.92
A32: Sameer Rizvi | B32: DC | C32: Anchor | D32: 0 | E32: 0 | F32: 0 | G32: 0 | H32: 0 | I32: 0 | J32: 0 | K32: 0 | Q32: 0
A33: Ashutosh Sharma | B33: DC | C33: Anchor | D33: 0 | E33: 0 | F33: 0 | G33: 0 | H33: 0 | I33: 0 | J33: 0 | K33: 0 | Q33: 0
A34: Vipraj Nigam | B34: DC | C34: All-Rounder | D34: 5 | E34: 9 | F34: 113 | G34: 2 | H34: 12.55 | I34: 0 | J34: 56.5 | K34: 56.5 | Q34: -69.6
A35: Ajay Mandal | B35: DC | C35: All-Rounder | D35: 0 | E35: 0 | F35: 0 | G35: 0 | H35: 0 | I35: 0 | J35: 0 | K35: 0 | Q35: 0
A36: Tripurana Vijay | B36: DC | C36: All-Rounder | D36: 0 | E36: 0 | F36: 0 | G36: 0 | H36: 0 | I36: 0 | J36: 0 | K36: 0 | Q36: 0
A37: Madhav Tiwari | B37: DC | C37: All-Rounder | D37: 3 | E37: 10 | F37: 87 | G37: 4 | H37: 8.7 | I37: 0 | J37: 21.75 | K37: 21.75 | Q37: -15.15
A38: Mitchell Starc | B38: DC | C38: Pacer | D38: 6 | E38: 22 | F38: 224 | G38: 11 | H38: 10.18 | I38: 0 | J38: 20.36 | K38: 20.363636 | L38: 0 | M38: 0 | N38: 0 | O38: 0 | P38: 0 | Q38: 25.28 | R38: Mitchell Starc_DC
A39: T Natarajan | B39: DC | C39: Pacer | D39: 10 | E39: 31.5 | F39: 356 | G39: 5 | H39: 11.18 | I39: 0 | J39: 71.2 | K39: 71.2 | L39: 0 | M39: 0 | N39: 0 | O39: 0 | P39: 0 | Q39: -63.56 | R39: T Natarajan_DC
A40: Mukesh Kumar | B40: DC | C40: Pacer | D40: 10 | E40: 31.2 | F40: 353 | G40: 6 | H40: 11.26 | I40: 0 | J40: 58.83 | K40: 58.833333 | L40: 1.6 | M40: 1.3333333 | N40: 0.11494253 | O40: 0 | P40: -23.6 | Q40: -39.671839 | R40: Mukesh Kumar_DC
...

Sheet Master_AllRounder_Analysis
A1: Player | B1: Team | C1: Role | D1: Batting Matches | E1: Runs | F1: Balls | G1: Bat Avg | H1: Strike Rate | I1: 4s | J1: 6s | K1: Bowling Matches | L1: Overs | M1: Runs Conceded | N1: Wickets | O1: Economy | P1: Maidens | Q1: Bowling Avg | R1: Batting Impact | S1: Bowling Impact
A2: Ruturaj Gaikwad | B2: CSK | C2: Anchor | D2: 14 | E2: 337 | F2: 273 | G2: 28.08 | H2: 123.44 | I2: 29 | J2: 12 | K2: 0 | L2: 0 | M2: 0 | N2: 0 | O2: 0 | P2: 0 | Q2: 0 | R2: 1168.1078 | S2: 0
A3: MS Dhoni | B3: CSK | C3: Wicketkeeper | D3: 0 | E3: 0 | F3: 0 | G3: 0 | H3: 0 | I3: 0 | J3: 0 | K3: 0 | L3: 0 | M3: 0 | N3: 0 | O3: 0 | P3: 0 | Q3: 0 | R3: 0 | S3: 0
A4: Dewald Brevis | B4: CSK | C4: Anchor | D4: 11 | E4: 151 | F4: 118 | G4: 18.87 | H4: 127.96 | I4: 8 | J4: 10 | K4: 0 | L4: 0 | M4: 0 | N4: 0 | O4: 0 | P4: 0 | Q4: 0 | R4: 364.60539 | S4: 0
A5: Akash Madhwal | B5: CSK | C5: Pacer | D5: 0 | E5: 0 | F5: 0 | G5: 0 | H5: 0 | I5: 0 | J5: 0 | K5: 0 | L5: 0 | M5: 0 | N5: 0 | O5: 0 | P5: 0 | Q5: 0 | R5: 0 | S5: 0
A6: Urvil Patel | B6: CSK | C6: Wicketkeeper | D6: 7 | E6: 129 | F6: 64 | G6: 18.42 | H6: 201.56 | I6: 6 | J6: 14 | K6: 0 | L6: 0 | M6: 0 | N6: 0 | O6: 0 | P6: 0 | Q6: 0 | R6: 478.94284 | S6: 0 | V6: Role | W6: (All)
A7: Anshul Kamboj | B7: CSK | C7: All-Rounder | D7: 14 | E7: 58 | F7: 38 | G7: 29 | H7: 152.63 | I7: 3 | J7: 4 | K7: 14 | L7: 50.2 | M7: 530 | N7: 21 | O7: 10.52 | P7: 0 | Q7: 25.23 | R7: 256.72366 | S7: 8.7562426
A8: Dian Forrester | B8: CSK | C8: All-Rounder | D8: 0 | E8: 0 | F8: 0 | G8: 0 | H8: 0 | I8: 0 | J8: 0 | K8: 0 | L8: 0 | M8: 0 | N8: 0 | O8: 0 | P8: 0 | Q8: 0 | R8: 0 | S8: 0 | V8: Row Labels | W8: Sum of Batting Impact | X8: Sum of Bowling Impact
A9: Macneil Noronha | B9: CSK | C9: All-Rounder | D9: 0 | E9: 0 | F9: 0 | G9: 0 | H9: 0 | I9: 0 | J9: 0 | K9: 0 | L9: 0 | M9: 0 | N9: 0 | O9: 0 | P9: 0 | Q9: 0 | R9: 0 | S9: 0 | V9: Shubman Gill | W9: 5459.3768 | X9: 0
A10: Shivam Dube | B10: CSK | C10: All-Rounder | D10: 13 | E10: 270 | F10: 170 | G10: 38.57 | H10: 158.82 | I10: 24 | J10: 15 | K10: 0 | L10: 0 | M10: 0 | N10: 0 | O10: 0 | P10: 0 | Q10: 0 | R10: 1653.9356 | S10: 0 | V10: Vaibhav Suryavanshi | W10: 8931.0228 | X10: 0
A11: Kuldip Yadav | B11: CSK | C11: Pacer | D11: 0 | E11: 0 | F11: 0 | G11: 0 | H11: 0 | I11: 0 | J11: 0 | K11: 0 | L11: 0 | M11: 0 | N11: 0 | O11: 0 | P11: 0 | Q11: 0 | R11: 0 | S11: 0 | V11: Virat Kohli | W11: 6296.7375 | X11: 0
A12: Noor Ahmad | B12: CSK | C12: Spinner | D12: 14 | E12: 11 | F12: 23 | G12: 3.66 | H12: 47.82 | I12: 0 | J12: 1 | K12: 14 | L12: 51 | M12: 428 | N12: 13 | O12: 8.39 | P12: 0 | Q12: 32.92 | R12: 1.9252332 | S12: 3.3131835 | V12: Grand Total | W12: 20687.137 | X12: 0
A13: Mukesh Choudhary | B13: CSK | C13: Pacer | D13: 0 | E13: 0 | F13: 0 | G13: 0 | H13: 0 | I13: 0 | J13: 0 | K13: 8 | L13: 28 | M13: 249 | N13: 8 | O13: 8.89 | P13: 0 | Q13: 31.12 | R13: 0 | S13: 2.285347
A14: Spencer Johnson | B14: CSK | C14: Pacer | D14: 0 | E14: 0 | F14: 0 | G14: 0 | H14: 0 | I14: 0 | J14: 0 | K14: 0 | L14: 0 | M14: 0 | N14: 0 | O14: 0 | P14: 0 | Q14: 0 | R14: 0 | S14: 0
A15: Shreyas Gopal | B15: CSK | C15: Spinner | D15: 0 | E15: 0 | F15: 0 | G15: 0 | H15: 0 | I15: 0 | J15: 0 | K15: 0 | L15: 0 | M15: 0 | N15: 0 | O15: 0 | P15: 0 | Q15: 0 | R15: 0 | S15: 0
A16: Gurjapneet Singh | B16: CSK | C16: Pacer | D16: 0 | E16: 0 | F16: 0 | G16: 0 | H16: 0 | I16: 0 | J16: 0 | K16: 8 | L16: 25.1 | M16: 233 | N16: 4 | O16: 9.25 | P16: 0 | Q16: 58.25 | R16: 0 | S16: 0.63519313
A17: Sanju Samson | B17: CSK | C17: Wicketkeeper | D17: 14 | E17: 477 | F17: 288 | G17: 43.36 | H17: 165.62 | I17: 53 | J17: 24 | K17: 0 | L17: 0 | M17: 0 | N17: 0 | O17: 0 | P17: 0 | Q17: 0 | R17: 3425.4721 | S17: 0
A18: Akeal Hosein | B18: CSK | C18: Pacer | D18: 7 | E18: 5 | F18: 3 | G18: - | H18: 166.66 | I18: 0 | J18: 0 | K18: 7 | L18: 24.4 | M18: 198 | N18: 8 | O18: 8.02 | P18: 1 | Q18: 24.75 | R18: #VALUE! | S18: 2.5923232
A19: Prashant Veer | B19: CSK | C19: All-Rounder | D19: 6 | E19: 90 | F19: 67 | G19: 45 | H19: 134.32 | I19: 10 | J19: 3 | K19: 0 | L19: 0 | M19: 0 | N19: 0 | O19: 0 | P19: 0 | Q19: 0 | R19: 543.996 | S19: 0
A20: Kartik Sharma | B20: CSK | C20: Wicketkeeper | D20: 11 | E20: 295 | F20: 216 | G20: 32.77 | H20: 136.57 | I20: 24 | J20: 16 | K20: 0 | L20: 0 | M20: 0 | N20: 0 | O20: 0 | P20: 0 | Q20: 0 | R20: 1320.2427 | S20: 0
A21: Matthew Short | B21: CSK | C21: All-Rounder | D21: 3 | E21: 60 | F21: 51 | G21: 20 | H21: 117.64 | I21: 6 | J21: 1 | K21: 0 | L21: 0 | M21: 0 | N21: 0 | O21: 0 | P21: 0 | Q21: 0 | R21: 141.168 | S21: 0
A22: Aman Khan | B22: CSK | C22: All-Rounder | D22: 0 | E22: 0 | F22: 0 | G22: 0 | H22: 0 | I22: 0 | J22: 0 | K22: 0 | L22: 0 | M22: 0 | N22: 0 | O22: 0 | P22: 0 | Q22: 0 | R22: 0 | S22: 0
A23: Sarfaraz Khan | B23: CSK | C23: Anchor | D23: 0 | E23: 0 | F23: 0 | G23: 0 | H23: 0 | I23: 0 | J23: 0 | K23: 0 | L23: 0 | M23: 0 | N23: 0 | O23: 0 | P23: 0 | Q23: 0 | R23: 0 | S23: 0
A24: Rahul Chahar | B24: CSK | C24: Spinner | D24: 0 | E24: 0 | F24: 0 | G24: 0 | H24: 0 | I24: 0 | J24: 0 | K24: 0 | L24: 0 | M24: 0 | N24: 0 | O24: 0 | P24: 0 | Q24: 0 | R24: 0 | S24: 0
A25: Matt Henry | B25: CSK | C25: Pacer | D25: 3 | E25: 7 | F25: 10 | G25: 3.5 | H25: 70 | I25: 1 | J25: 0 | K25: 3 | L25: 10 | M25: 130 | N25: 2 | O25: 13 | P25: 0 | Q25: 65 | R25: 1.715 | S25: 0.4
A26: Zak Foulkes | B26: CSK | C26: All-Rounder | D26: 0 | E26: 0 | F26: 0 | G26: 0 | H26: 0 | I26: 0 | J26: 0 | K26: 0 | L26: 0 | M26: 0 | N26: 0 | O26: 0 | P26: 0 | Q26: 0 | R26: 0 | S26: 0
A27: KL Rahul | B27: DC | C27: Wicketkeeper | D27: 14 | E27: 593 | F27: 340 | G27: 45.61 | H27: 174.41 | I27: 56 | J27: 31 | K27: 0 | L27: 0 | M27: 0 | N27: 0 | O27: 0 | P27: 0 | Q27: 0 | R27: 4717.2202 | S27: 0
A28: Karun Nair | B28: DC | C28: Anchor | D28: 2 | E28: 18 | F28: 18 | G28: 9 | H28: 100 | I28: 3 | J28: 0 | K28: 0 | L28: 0 | M28: 0 | N28: 0 | O28: 0 | P28: 0 | Q28: 0 | R28: 16.2 | S28: 0
A29: Abishek Porel | B29: DC | C29: Wicketkeeper | D29: 4 | E29: 108 | F29: 88 | G29: 27 | H29: 122.72 | I29: 15 | J29: 1 | K29: 0 | L29: 0 | M29: 0 | N29: 0 | O29: 0 | P29: 0 | Q29: 0 | R29: 357.85152 | S29: 0
A30: Tristan Stubbs | B30: DC | C30: Anchor | D30: 14 | E30: 275 | F30: 216 | G30: 34.37 | H30: 127.31 | I30: 18 | J30: 9 | K30: 0 | L30: 0 | M30: 0 | N30: 0 | O30: 0 | P30: 0 | Q30: 0 | R30: 1203.3023 | S30: 0
... A36: Tripurana Vijay | B36: DC | C36: All-Rounder | D36: 0 | E36: 0 | F36: 0 | G36: 0 | H36: 0 | I36: 0 | J36: 0 | K36: 0 | L36: 0 | M36: 0 | N36: 0 | O36: 0 | P36: 0 | Q36: 0 | R36: 0 | S36: 0
A37: Madhav Tiwari | B37: DC | C37: All-Rounder | D37: 3 | E37: 18 | F37: 8 | G37: - | H37: 225 | I37: 2 | J37: 1 | K37: 3 | L37: 10 | M37: 87 | N37: 4 | O37: 8.7 | P37: 0 | Q37: 21.75 | R37: #VALUE! | S37: 1.6
A38: Mitchell Starc | B38: DC | C38: Pacer | D38: 0 | E38: 0 | F38: 0 | G38: 0 | H38: 0 | I38: 0 | J38: 0 | K38: 6 | L38: 22 | M38: 224 | N38: 11 | O38: 10.18 | P38: 0 | Q38: 20.36 | R38: 0 | S38: 5.5
A39: T Natarajan | B39: DC | C39: Pacer | D39: 0 | E39: 0 | F39: 0 | G39: 0 | H39: 0 | I39: 0 | J39: 0 | K39: 10 | L39: 31.5 | M39: 356 | N39: 5 | O39: 11.18 | P39: 0 | Q39: 71.2 | R39: 0 | S39: 0.78511236
A40: Mukesh Kumar | B40: DC | C40: Pacer | D40: 0 | E40: 0 | F40: 0 | G40: 0 | H40: 0 | I40: 0 | J40: 0 | K40: 10 | L40: 31.2 | M40: 353 | N40: 6 | O40: 11.26 | P40: 0 | Q40: 58.83 | R40: 0 | S40: 1.1483937
A41: Dushmantha Chameera | B41: DC | C41: Pacer | D41: 0 | E41: 0 | F41: 0 | G41: 0 | H41: 0 | I41: 0 | J41: 0 | K41: 0 | L41: 0 | M41: 0 | N41: 0 | O41: 0 | P41: 0 | Q41: 0 | R41: 0 | S41: 0
A42: Kuldeep Yadav | B42: DC | C42: Spinner | D42: 12 | E42: 9 | F42: 21 | G42: 3 | H42: 42.85 | I42: 0 | J42: 0 | K42: 12 | L42: 37 | M42: 381 | N42: 10 | O42: 10.29 | P42: 0 | Q42: 38.1 | R42: 1.15695 | S42: 2.7007874
A43: Nitish Rana | B43: DC | C43: Anchor | D43: 9 | E43: 225 | F43: 149 | G43: 25 | H43: 151 | I43: 27 | J43: 10 | K43: 0 | L43: 0 | M43: 0 | N43: 0 | O43: 0 | P43: 0 | Q43: 0 | R43: 849.375 | S43: 0
A44: Auqib Nabi | B44: DC | C44: All-Rounder | D44: 5 | E44: 14 | F44: 4 | G44: 14 | H44: 350 | I44: 2 | J44: 1 | K44: 0 | L44: 0 | M44: 0 | N44: 0 | O44: 0 | P44: 0 | Q44: 0 | R44: 68.6 | S44: 0
A45: Rehan Ahmed | B45: DC | C45: Pacer | D45: 0 | E45: 0 | F45: 0 | G45: 0 | H45: 0 | I45: 0 | J45: 0 | K45: 0 | L45: 0 | M45: 0 | N45: 0 | O45: 0 | P45: 0 | Q45: 0 | R45: 0 | S45: 0
...

Sheet Team_Analytics
A1: Team | B1: Total Squad Cost | C1: Total Runs | D1: Total Wickets | E1: Avg Batting Impact | F1: Avg Bowling Impact | G1: Team Strength Score | H1: Squad Efficiency | I1: Team Rank | J1: Value Grade | K1: Dominance Score | L1: Balance Index | M1: Best Team | N1: Best Value Team | O1: Most Dominant Team | P1: Most Balance Team
A2: MI | B2: 2.75 | C2: 2098 | D2: 61 | E2: 83.92 | F2: 2.44 | G2: 86.36 | H2: 785.09091 | I2: 4 | J2: 1 | K2: 2159 | L2: 81.48 | M2: GT | N2: MI | O2: GT | P2: RCB
A3: GT | B3: 9.7 | C3: 2739 | D3: 100 | E3: 109.56 | F3: 4 | G3: 113.56 | H3: 292.68041 | I3: 1 | J3: 2 | K3: 2839 | L3: 105.56 | M3: GT | N3: MI | O3: GT | P3: RCB
A4: PBKS | B4: 8 | C4: 1799 | D4: 50 | E4: 71.96 | F4: 2 | G4: 73.96 | H4: 231.125 | I4: 6 | J4: 3 | K4: 1849 | L4: 69.96 | M4: GT | N4: MI | O4: GT | P4: RCB
A5: RR | B5: 12.75 | C5: 2027 | D5: 87 | E5: 81.08 | F5: 3.48 | G5: 84.56 | H5: 165.80392 | I5: 5 | J5: 4 | K5: 2114 | L5: 77.6 | M5: GT | N5: MI | O5: GT | P5: RCB
A6: SRH | B6: 19.35 | C6: 2630 | D6: 87 | E6: 105.2 | F6: 3.48 | G6: 108.68 | H6: 140.41344 | I6: 2 | J6: 5 | K6: 2717 | L6: 101.72 | M6: GT | N6: MI | O6: GT | P6: RCB
A7: LSG | B7: 17.4 | C7: 2134 | D7: 54 | E7: 85.36 | F7: 2.16 | G7: 87.52 | H7: 125.74713 | I7: 3 | J7: 6 | K7: 2188 | L7: 83.2 | M7: GT | N7: MI | O7: GT | P7: RCB
A8: DC | B8: 20.2 | C8: 1721 | D8: 62 | E8: 68.84 | F8: 2.48 | G8: 71.32 | H8: 88.267327 | I8: 8 | J8: 7 | K8: 1783 | L8: 66.36 | M8: GT | N8: MI | O8: GT | P8: RCB
A9: RCB | B9: 17.75 | C9: 1474 | D9: 55 | E9: 58.96 | F9: 2.2 | G9: 61.16 | H9: 86.140845 | I9: 10 | J9: 8 | K9: 1529 | L9: 56.76 | M9: GT | N9: MI | O9: GT | P9: RCB
A10: CSK | B10: 39.95 | C10: 1754 | D10: 54 | E10: 70.16 | F10: 2.16 | G10: 72.32 | H10: 45.256571 | I10: 7 | J10: 9 | K10: 1808 | L10: 68 | M10: GT | N10: MI | O10: GT | P10: RCB
A11: KKR | B11: 37 | C11: 1604 | D11: 56 | E11: 64.16 | F11: 2.24 | G11: 66.4 | H11: 44.864865 | I11: 9 | J11: 10 | K11: 1660 | L11: 61.92 | M11: GT | N11: MI | O11: GT | P11: RCB
L13: Row Labels | M13: Sum of Squad Efficiency
B14: Row Labels | C14: Sum of Total Squad Cost | E14: Row Labels | F14: Sum of Team Strength Score | H14: Row Labels | I14: Sum of Squad Efficiency | L14: CSK | M14: 45.256571
B15: CSK | C15: 39.95 | E15: CSK | F15: 72.32 | H15: CSK | I15: 45.256571 | L15: DC | M15: 88.267327
B16: DC | C16: 20.2 | E16: DC | F16: 71.32 | H16: DC | I16: 88.267327 | L16: GT | M16: 292.68041
B17: GT | C17: 9.7 | E17: GT | F17: 113.56 | H17: GT | I17: 292.68041 | L17: KKR | M17: 44.864865
B18: KKR | C18: 37 | E18: KKR | F18: 66.4 | H18: KKR | I18: 44.864865 | L18: LSG | M18: 125.74713
B19: LSG | C19: 17.4 | E19: LSG | F19: 87.52 | H19: LSG | I19: 125.74713 | L19: MI | M19: 785.09091
B20: MI | C20: 2.75 | E20: MI | F20: 86.36 | H20: MI | I20: 785.09091 | L20: PBKS | M20: 231.125
B21: PBKS | C21: 8 | E21: PBKS | F21: 73.96 | H21: PBKS | I21: 231.125 | L21: RCB | M21: 86.140845
B22: RCB | C22: 17.75 | E22: RCB | F22: 61.16 | H22: RCB | I22: 86.140845 | L22: RR | M22: 165.80392
B23: RR | C23: 12.75 | E23: RR | F23: 84.56 | H23: RR | I23: 165.80392 | L23: SRH | M23: 140.41344
B24: SRH | C24: 19.35 | E24: SRH | F24: 108.68 | H24: SRH | I24: 140.41344 | L24: Grand Total | M24: 2005.3904
B25: Grand Total | C25: 184.85 | E25: Grand Total | F25: 825.84 | H25: Grand Total | I25: 2005.3904

Sheet Player_Master_Clean
A1: Player | B1: Team | C1: Acquisition | D1: Role | E1: Price | F1: key | G1: Uncapped Player Value
A2: Ruturaj Gaikwad | B2: CSK | C2: Retained | D2: Anchor | E2: 0 | F2: Ruturaj Gaikwad_CSK
A3: MS Dhoni | B3: CSK | C3: Retained | D3: Wicketkeeper | E3: 0 | F3: MS Dhoni_CSK | H3: Row Labels | I3: Sum of Price
A4: Dewald Brevis | B4: CSK | C4: Retained | D4: Anchor | E4: 0 | F4: Dewald Brevis_CSK | H4: All-Rounder | I4: 98.6
A5: Akash Madhwal | B5: CSK | C5: Replacement | D5: Pacer | E5: 0.3 | F5: Akash Madhwal_CSK | G5: 0 | H5: Anchor | I5: 21
A6: Urvil Patel | B6: CSK | C6: Retained | D6: Wicketkeeper | E6: 0 | F6: Urvil Patel_CSK | H6: Pacer | I6: 30.6
A7: Anshul Kamboj | B7: CSK | C7: Retained | D7: All-Rounder | E7: 0 | F7: Anshul Kamboj_CSK | H7: Spinner | I7: 8.8
A8: Akeal Hosein | B8: CSK | C8: Auction | D8: Pacer | E8: 2 | F8: Akeal Hosein_CSK | G8: 0 | H8: Wicketkeeper | I8: 25.85
A9: Aman Khan | B9: CSK | C9: Auction | D9: All-Rounder | E9: 0.4 | F9: Aman Khan_CSK | G9: 0 | H9: (blank)
A10: Shivam Dube | B10: CSK | C10: Retained | D10: All-Rounder | E10: 0 | F10: Shivam Dube_CSK | H10: Grand Total | I10: 184.85
A11: Aman Rao | B11: RR | C11: Auction | D11: Anchor | E11: 0.3 | F11: Aman Rao_RR | G11: 7.21
A12: Noor Ahmad | B12: CSK | C12: Retained | D12: Spinner | E12: 0 | F12: Noor Ahmad_CSK
A13: Mukesh Choudhary | B13: CSK | C13: Retained | D13: Pacer | E13: 0 | F13: Mukesh Choudhary_CSK
A14: Amit Kumar | B14: SRH | C14: Auction | D14: Pacer | E14: 0.3 | F14: Amit Kumar_SRH | G14: 0
A15: Shreyas Gopal | B15: CSK | C15: Retained | D15: Spinner | E15: 0 | F15: Shreyas Gopal_CSK
A16: Gurjapneet Singh | B16: CSK | C16: Retained | D16: Pacer | E16: 0 | F16: Gurjapneet Singh_CSK
A17: Sanju Samson | B17: CSK | C17: Trade | D17: Wicketkeeper | E17: 0 | F17: Sanju Samson_CSK
A18: Anrich Nortje | B18: LSG | C18: Auction | D18: Pacer | E18: 2 | F18: Anrich Nortje_LSG | G18: 4.0718542
A19: Prashant Veer | B19: CSK | C19: Auction | D19: All-Rounder | E19: 14.2 | F19: Prashant Veer_CSK
A20: Kartik Sharma | B20: CSK | C20: Auction | D20: Wicketkeeper | E20: 14.2 | F20: Kartik Sharma_CSK
A21: Ashok Sharma | B21: GT | C21: Auction | D21: Pacer | E21: 0.9 | F21: Ashok Sharma_GT | G21: 8.262697
A22: Blessing Muzarabani | B22: KKR | C22: Replacement | D22: Pacer | E22: 0 | F22: Blessing Muzarabani_KKR | G22: 0
A23: Brijesh Sharma | B23: RR | C23: Auction | D23: Spinner | E23: 0.3 | F23: Brijesh Sharma_RR | G23: 92.974836
A24: Connor Esterhuizen | B24: GT | C24: Replacement | D24: Wicketkeeper | E24: 0.75 | F24: Connor Esterhuizen_GT | G24: -21.435216
A25: Daksh Kamra | B25: KKR | C25: Auction | D25: All-Rounder | E25: 0.3 | F25: Daksh Kamra_KKR | G25: 0
A26: Danish Malewar | B26: MI | C26: Auction | D26: Anchor | E26: 0.3 | F26: Danish Malewar_MI | G26: 32.08
A27: KL Rahul | B27: DC | C27: Retained | D27: Wicketkeeper | E27: 0 | F27: KL Rahul_DC
A28: Karun Nair | B28: DC | C28: Retained | D28: Anchor | E28: 0 | F28: Karun Nair_DC
A29: Abishek Porel | B29: DC | C29: Retained | D29: Wicketkeeper | E29: 0 | F29: Abishek Porel_DC
A30: Tristan Stubbs | B30: DC | C30: Retained | D30: Anchor | E30: 0 | F30: Tristan Stubbs_DC
A31: Axar Patel | B31: DC | C31: Retained | D31: All-Rounder | E31: 0 | F31: Axar Patel_DC
A32: Sameer Rizvi | B32: DC | C32: Retained | D32: Anchor | E32: 0 | F32: Sameer Rizvi_DC
A33: Ashutosh Sharma | B33: DC | C33: Retained | D33: Anchor | E33: 0 | F33: Ashutosh Sharma_DC
A34: Vipraj Nigam | B34: DC | C34: Retained | D34: All-Rounder | E34: 0 | F34: Vipraj Nigam_DC
A35: Ajay Mandal | B35: DC | C35: Retained | D35: All-Rounder | E35: 0 | F35: Ajay Mandal_DC
A36: Tripurana Vijay | B36: DC | C36: Retained | D36: All-Rounder | E36: 0 | F36: Tripurana Vijay_DC
A37: Madhav Tiwari | B37: DC | C37: Retained | D37: All-Rounder | E37: 0 | F37: Madhav Tiwari_DC
A38: Mitchell Starc | B38: DC | C38: Retained | D38: Pacer | E38: 0 | F38: Mitchell Starc_DC
... A44: Auqib Nabi | B44: DC | C44: Auction | D44: All-Rounder | E44: 8.4 | F44: Auqib Nabi_DC
A45: Dasun Shanaka | B45: RR | C45: Replacement | D45: All-Rounder | E45: 0 | F45: Dasun Shanaka_RR | G45: 3.5883363
...

Sheet Batting_Clean
A1: Player | B1: Team | C1: Matches | D1: Runs | E1: Balls | F1: Average | G1: Strike Rate | H1: 100s | I1: 50s | J1: 4s | K1: 6s | L1: Not Outs | M1: Key
A2: Vaibhav Suryavanshi | B2: RR | C2: 16 | D2: 776 | E2: 327 | F2: 48.5 | G2: 237.3 | H2: 1 | I2: 5 | J2: 63 | K2: 72 | L2: 0 | M2: Vaibhav_Suryavanshi_RR
A3: Shubman Gill | B3: GT | C3: 16 | D3: 732 | E3: 449 | F3: 45.75 | G3: 163.02 | H3: 1 | I3: 6 | J3: 74 | K3: 33 | L3: 0 | M3: Shubman_Gill_GT
A4: B Sai Sudharsan | B4: GT | C4: 17 | D4: 722 | E4: 457 | F4: 45.12 | G4: 157.98 | H4: 1 | I4: 8 | J4: 75 | K4: 30 | L4: 1 | M4: B_Sai_Sudharsan_GT
A5: Virat Kohli | B5: RCB | C5: 16 | D5: 675 | E5: 407 | F5: 56.25 | G5: 165.84 | H5: 1 | I5: 5 | J5: 73 | K5: 25 | L5: 4 | M5: Virat_Kohli_RCB
A6: Heinrich Klaasen | B6: SRH | C6: 15 | D6: 624 | E6: 390 | F6: 48 | G6: 160 | H6: 0 | I6: 6 | J6: 48 | K6: 31 | L6: 2 | M6: Heinrich_Klaasen_SRH
A7: Ishan Kishan | B7: SRH | C7: 15 | D7: 602 | E7: 330 | F7: 40.13 | G7: 182.42 | H7: 0 | I7: 6 | J7: 60 | K7: 32 | L7: 0 | M7: Ishan_Kishan_SRH
A8: KL Rahul | B8: DC | C8: 14 | D8: 593 | E8: 340 | F8: 45.61 | G8: 174.41 | H8: 1 | I8: 5 | J8: 56 | K8: 31 | L8: 1 | M8: KL_Rahul_DC
A9: Abhishek Sharma | B9: SRH | C9: 15 | D9: 563 | E9: 275 | F9: 40.21 | G9: 204.72 | H9: 1 | I9: 4 | J9: 50 | K9: 43 | L9: 1 | M9: Abhishek_Sharma_SRH
A10: Mitchell Marsh | B10: LSG | C10: 13 | D10: 563 | E10: 345 | F10: 43.3 | G10: 163.18 | H10: 1 | I10: 3 | J10: 51 | K10: 36 | L10: 0 | M10: Mitchell_Marsh_LSG
A11: Jos Buttler | B11: GT | C11: 17 | D11: 526 | E11: 345 | F11: 37.57 | G11: 152.46 | H11: 0 | I11: 4 | J11: 51 | K11: 26 | L11: 3 | M11: Jos_Buttler_GT
A12: Dhruv Jurel | B12: RCB | C12: 16 | D12: 515 | E12: 333 | F12: 36.78 | G12: 154.65 | H12: 0 | I12: 6 | J12: 47 | K12: 24 | L12: 2 | M12: Dhruv_Jurel_RCB
A13: Prabhsimran Singh | B13: PBKS | C13: 14 | D13: 510 | E13: 302 | F13: 42.5 | G13: 168.87 | H13: 0 | I13: 6 | J13: 55 | K13: 23 | L13: 1 | M13: Prabhsimran_Singh_PBKS
... A91: Anshul Kamboj | B91: CSK | C91: 14 | D91: 58 | E91: 38 | F91: 29 | G91: 152.63 | H91: 0 | I91: 0 | J91: 3 | K91: 4 | L91: 2 | M91: Anshul_Kamboj_CSK
A92: Shahbaz Ahmed | B92: LSG | C92: 5 | D92: 58 | E92: 41 | F92: - | G92: 141.46 | H92: 0 | I92: 0 | J92: 4 | K92: 3 | L92: 2 | M92: Shahbaz_Ahmed_LSG
A93: Shivang Kumar | B93: SRH | C93: 13 | D93: 53 | E93: 46 | F93: 8.83 | G93: 115.21 | H93: 0 | I93: 0 | J93: 6 | K93: 1 | L93: 0 | M93: Shivang_Kumar_SRH
A94: Azmatullah Omarzai | B94: PBKS | C94: 3 | D94: 52 | E94: 27 | F94: 26 | G94: 192.59 | H94: 0 | I94: 0 | J94: 3 | K94: 5 | L94: 0 | M94: Azmatullah_Omarzai_PBKS
A95: Arshin Kulkarni | B95: PBKS | C95: 14 | D95: 52 | E95: 39 | F95: 13 | G95: 133.33 | H95: 0 | I95: 0 | J95: 3 | K95: 2 | L95: 3 | M95: Arshin_Kulkarni_PBKS
A96: Marco Jansen | B96: LSG | C96: 13 | D96: 51 | E96: 45 | F96: 12.75 | G96: 113.33 | H96: 0 | I96: 0 | J96: 1 | K96: 3 | L96: 1 | M96: Marco_Jansen_LSG
A97: Corbin Bosch | B97: PBKS | C97: 6 | D97: 50 | E97: 31 | F97: 50 | G97: 161.29 | H97: 0 | I97: 0 | J97: 5 | K97: 2 | L97: 3 | M97: Corbin_Bosch_PBKS
A98: Rashid Khan | B98: GT | C98: 17 | D98: 50 | E98: 41 | F98: 12.5 | G98: 121.95 | H98: 0 | I98: 0 | J98: 4 | K98: 2 | L98: 2 | M98: Rashid_Khan_GT
A99: Kagiso Rabada | B99: GT | C99: 17 | D99: 47 | E99: 38 | F99: 23.5 | G99: 123.68 | H99: 0 | I99: 0 | J99: 5 | K99: 2 | L99: 2 | M99: Kagiso_Rabada_GT
A100: Sahil Parakh | B100: PBKS | C100: 4 | D100: 46 | E100: 33 | F100: 11.5 | G100: 139.39 | H100: 0 | I100: 0 | J100: 5 | K100: 2 | L100: 0 | M100: Sahil_Parakh_PBKS
A101: M Shahrukh Khan | B101: GT | C101: 9 | D101: 43 | E101: 33 | F101: 10.75 | G101: 130.3 | H101: 0 | I101: 0 | J101: 3 | K101: 2 | L101: 1 | M101: M_Shahrukh_Khan_GT
A102: Sunil Narine | B102: KKR | C102: 13 | D102: 40 | E102: 32 | F102: 13.33 | G102: 125 | H102: 0 | I102: 0 | J102: 2 | K102: 4 | L102: 1 | M102: Sunil_Narine_KKR
A103: Bhuvneshwar Kumar | B103: SRH | C103: 16 | D103: 34 | E103: 26 | F103: - | G103: 130.76 | H103: 0 | I103: 0 | J103: 3 | K103: 1 | L103: 4 | M103: Bhuvneshwar_Kumar_SRH
A104: George Linde | B104: PBKS | C104: 3 | D104: 31 | E104: 21 | F104: 10.33 | G104: 147.61 | H104: 0 | I104: 0 | J104: 6 | K104: 0 | L104: 0 | M104: George_Linde_PBKS
A105: Mohammed Shami | B105: SRH | C105: 13 | D105: 31 | E105: 22 | F105: 6.2 | G105: 140.9 | H105: 0 | I105: 0 | J105: 2 | K105: 3 | L105: 2 | M105: Mohammed_Shami_SRH
A106: Pat Cummins | B106: SRH | C106: 8 | D106: 30 | E106: 19 | F106: 10 | G106: 157.89 | H106: 0 | I106: 0 | J106: 1 | K106: 3 | L106: 0 | M106: Pat_Cummins_SRH
A107: Xavier Bartlett | B107: DC | C107: 9 | D107: 29 | E107: 13 | F107: 29 | G107: 223.07 | H107: 0 | I107: 0 | J107: 2 | K107: 2 | L107: 2 | M107: Xavier_Bartlett_DC
A108: Akshat Raghuwanshi | B108: LSG | C108: 3 | D108: 29 | E108: 25 | F108: 14.5 | G108: 116 | H108: 0 | I108: 0 | J108: 1 | K108: 1 | L108: 0 | M108: Akshat_Raghuwanshi_LSG
A109: Tushar Deshpande | B109: RR | C109: 7 | D109: 26 | E109: 14 | F109: 13 | G109: 185.71 | H109: 0 | I109: 0 | J109: 0 | K109: 3 | L109: 0 | M109: Tushar_Deshpande_RR
A110: Mitchell Santner | B110: CSK | C110: 4 | D110: 26 | E110: 19 | F110: - | G110: 136.84 | H110: 0 | I110: 0 | J110: 3 | K110: 0 | L110: 2 | M110: Mitchell_Santner_CSK
A111: Deepak Chahar | B111: CSK | C111: 8 | D111: 25 | E111: 19 | F111: 12.5 | G111: 131.57 | H111: 0 | I111: 0 | J111: 3 | K111: 1 | L111: 2 | M111: Deepak_Chahar_CSK
A112: Shardul Thakur | B112: MI | C112: 9 | D112: 24 | E112: 30 | F112: 12 | G112: 80 | H112: 0 | I112: 0 | J112: 2 | K112: 0 | L112: 1 | M112: Shardul_Thakur_MI
A113: Arshad Khan | B113: GT | C113: 8 | D113: 23 | E113: 11 | F113: 23 | G113: 209.09 | H113: 0 | I113: 0 | J113: 1 | K113: 2 | L113: 1 | M113: Arshad_Khan_GT
A114: Tim Seifert | B114: DC | C114: 3 | D114: 19 | E114: 18 | F114: 6.33 | G114: 105.55 | H114: 0 | I114: 0 | J114: 2 | K114: 1 | L114: 0 | M114: Tim_Seifert_DC
A115: Ravichandran Smaran | B115: SRH | C115: 6 | D115: 19 | E115: 25 | F115: 6.33 | G115: 76 | H115: 0 | I115: 0 | J115: 3 | K115: 0 | L115: 1 | M115: Ravichandran_Smaran_SRH
A116: Madhav Tiwari | B116: PBKS | C116: 3 | D116: 18 | E116: 8 | F116: - | G116: 225 | H116: 0 | I116: 0 | J116: 2 | K116: 1 | L116: 1 | M116: Madhav_Tiwari_PBKS
A117: Kumar Kushagra | B117: GT | C117: 1 | D117: 18 | E117: 14 | F117: 18 | G117: 128.57 | H117: 0 | I117: 0 | J117: 3 | K117: 0 | L117: 0 | M117: Kumar_Kushagra_GT
...

Sheet Bowling_Clean
A1: Player | B1: Team | C1: Matches | D1: Overs | E1: Runs Conceded | F1: Wickets | G1: Economy | H1: Maidens | I1: Average | J1: Key
A2: Kagiso Rabada | B2: GT | C2: 17 | D2: 64.4 | E2: 626 | F2: 29 | G2: 9.68 | H2: 1 | I2: 21.58 | J2: Kagiso_Rabada_GT
A3: Bhuvneshwar Kumar | B3: SRH | C3: 16 | D3: 63 | E3: 501 | F3: 28 | G3: 7.95 | H3: 0 | I3: 17.89 | J3: Bhuvneshwar_Kumar_SRH
A4: Jofra Archer | B4: RR | C4: 16 | D4: 60 | E4: 559 | F4: 25 | G4: 9.31 | H4: 1 | I4: 22.36 | J4: Jofra_Archer_RR
A5: Rashid Khan | B5: GT | C5: 17 | D5: 56.5 | E5: 516 | F5: 21 | G5: 9.07 | H5: 0 | I5: 24.57 | J5: Rashid_Khan_GT
A6: Anshul Kamboj | B6: CSK | C6: 14 | D6: 50.2 | E6: 530 | F6: 21 | G6: 10.52 | H6: 0 | I6: 25.23 | J6: Anshul_Kamboj_CSK
A7: Eshan Malinga | B7: SRH | C7: 15 | D7: 54.2 | E7: 507 | F7: 20 | G7: 9.33 | H7: 0 | I7: 25.35 | J7: Eshan_Malinga_SRH
A8: Mohammed Siraj | B8: GT | C8: 17 | D8: 62 | E8: 562 | F8: 19 | G8: 9.06 | H8: 1 | I8: 29.57 | J8: Mohammed_Siraj_GT
A9: Rasikh Salam | B9: RCB | C9: 12 | D9: 42.5 | E9: 405 | F9: 19 | G9: 9.45 | H9: 1 | I9: 21.31 | J9: Rasikh_Salam_RCB
A10: Kartik Tyagi | B10: KKR | C10: 14 | D10: 51 | E10: 498 | F10: 18 | G10: 9.76 | H10: 0 | I10: 27.66 | J10: Kartik_Tyagi_KKR
A11: Jason Holder | B11: KKR | C11: 11 | D11: 38.2 | E11: 290 | F11: 17 | G11: 7.56 | H11: 0 | I11: 17.05 | J11: Jason_Holder_KKR
A12: Prince Yadav | B12: LSG | C12: 14 | D12: 52 | E12: 459 | F12: 16 | G12: 8.82 | H12: 0 | I12: 28.68 | J12: Prince_Yadav_LSG
A13: Prasidh Krishna | B13: GT | C13: 12 | D13: 39 | E13: 407 | F13: 16 | G13: 10.43 | H13: 0 | I13: 25.43 | J13: Prasidh_Krishna_GT
... A101: Ramandeep Singh | B101: KKR | C101: 8 | D101: 2.4 | E101: 31 | F101: 1 | G101: 11.62 | H101: 0 | I101: 31 | J101: Ramandeep_Singh_KKR

Sheet Captain_Clean
A1: Captain | B1: Current Team | C1: Matches | D1: Wins | E1: Losses | F1: Win % | G1: NRR | H1: Win/Loss Ratio | I1: Leadership Score
A2: Rajat Patidar | B2: Royal Challengers Bengaluru | C2: 14 | D2: 9 | E2: 5 | F2: 64.29 | G2: 0.783 | H2: 1.8 | I2: 64.285714
A3: Shubman Gill | B3: Gujarat Titans | C3: 14 | D3: 9 | E3: 5 | F3: 64.29 | G3: 0.695 | H3: 1.8 | I3: 64.285714
A4: Pat Cummins | B4: Sunrisers Hyderabad | C4: 14 | D4: 9 | E4: 5 | F4: 64.29 | G4: 0.524 | H4: 1.8 | I4: 64.285714
A5: Riyan Parag | B5: Rajasthan Royals | C5: 14 | D5: 8 | E5: 6 | F5: 57.14 | G5: 0.189 | H5: 1.33 | I5: 57.142857
A6: Shreyas Iyer | B6: Punjab Kings | C6: 14 | D6: 7 | E6: 6 | F6: 50 | G6: 0.309 | H6: 1.17 | I6: 50
A7: Axar Patel | B7: Delhi Capitals | C7: 14 | D7: 7 | E7: 7 | F7: 50 | G7: -0.651 | H7: 1 | I7: 50
A8: Ajinkya Rahane | B8: Kolkata Knight Riders | C8: 14 | D8: 6 | E8: 7 | F8: 42.86 | G8: -0.147 | H8: 0.86 | I8: 42.857143
